{
 "cells": [
  {
   "cell_type": "code",
   "execution_count": 10,
   "metadata": {},
   "outputs": [
    {
     "name": "stdout",
     "output_type": "stream",
     "text": [
      "Note: you may need to restart the kernel to use updated packages.\n"
     ]
    },
    {
     "name": "stderr",
     "output_type": "stream",
     "text": [
      "WARNING: Retrying (Retry(total=4, connect=None, read=None, redirect=None, status=None)) after connection broken by 'NewConnectionError('<pip._vendor.urllib3.connection.HTTPSConnection object at 0x0000028C377691B0>: Failed to establish a new connection: [Errno 11001] getaddrinfo failed')': /simple/pandas/\n",
      "WARNING: Retrying (Retry(total=3, connect=None, read=None, redirect=None, status=None)) after connection broken by 'NewConnectionError('<pip._vendor.urllib3.connection.HTTPSConnection object at 0x0000028C377694E0>: Failed to establish a new connection: [Errno 11001] getaddrinfo failed')': /simple/pandas/\n",
      "WARNING: Retrying (Retry(total=2, connect=None, read=None, redirect=None, status=None)) after connection broken by 'NewConnectionError('<pip._vendor.urllib3.connection.HTTPSConnection object at 0x0000028C37769810>: Failed to establish a new connection: [Errno 11001] getaddrinfo failed')': /simple/pandas/\n",
      "WARNING: Retrying (Retry(total=1, connect=None, read=None, redirect=None, status=None)) after connection broken by 'NewConnectionError('<pip._vendor.urllib3.connection.HTTPSConnection object at 0x0000028C377699C0>: Failed to establish a new connection: [Errno 11001] getaddrinfo failed')': /simple/pandas/\n",
      "WARNING: Retrying (Retry(total=0, connect=None, read=None, redirect=None, status=None)) after connection broken by 'NewConnectionError('<pip._vendor.urllib3.connection.HTTPSConnection object at 0x0000028C37769B70>: Failed to establish a new connection: [Errno 11001] getaddrinfo failed')': /simple/pandas/\n",
      "ERROR: Could not find a version that satisfies the requirement pandas (from versions: none)\n",
      "ERROR: No matching distribution found for pandas\n",
      "\n",
      "[notice] A new release of pip available: 22.2.2 -> 22.3.1\n",
      "[notice] To update, run: C:\\Users\\Asus\\AppData\\Local\\Microsoft\\WindowsApps\\PythonSoftwareFoundation.Python.3.10_qbz5n2kfra8p0\\python.exe -m pip install --upgrade pip\n"
     ]
    }
   ],
   "source": [
    "pip install pandas"
   ]
  },
  {
   "cell_type": "code",
   "execution_count": 16,
   "metadata": {},
   "outputs": [
    {
     "ename": "ModuleNotFoundError",
     "evalue": "No module named 'pandas'",
     "output_type": "error",
     "traceback": [
      "\u001b[1;31m---------------------------------------------------------------------------\u001b[0m",
      "\u001b[1;31mModuleNotFoundError\u001b[0m                       Traceback (most recent call last)",
      "Cell \u001b[1;32mIn [16], line 1\u001b[0m\n\u001b[1;32m----> 1\u001b[0m \u001b[39mimport\u001b[39;00m \u001b[39mpandas\u001b[39;00m \u001b[39mas\u001b[39;00m \u001b[39mpd\u001b[39;00m\n\u001b[0;32m      2\u001b[0m \u001b[39mfrom\u001b[39;00m \u001b[39msklearn\u001b[39;00m\u001b[39m.\u001b[39;00m\u001b[39mensemble\u001b[39;00m \u001b[39mimport\u001b[39;00m RandomForestClassifier\n\u001b[0;32m      3\u001b[0m \u001b[39mfrom\u001b[39;00m \u001b[39msklearn\u001b[39;00m\u001b[39m.\u001b[39;00m\u001b[39mmetrics\u001b[39;00m \u001b[39mimport\u001b[39;00m accuracy_score\n",
      "\u001b[1;31mModuleNotFoundError\u001b[0m: No module named 'pandas'"
     ]
    }
   ],
   "source": [
    "import pandas as pd\n",
    "from sklearn.ensemble import RandomForestClassifier\n",
    "from sklearn.metrics import accuracy_score\n",
    "from sklearn.model_selection import train_test_split"
   ]
  },
  {
   "cell_type": "code",
   "execution_count": 7,
   "metadata": {},
   "outputs": [
    {
     "ename": "SyntaxError",
     "evalue": "invalid character '”' (U+201D) (2510796748.py, line 19)",
     "output_type": "error",
     "traceback": [
      "\u001b[1;36m  Cell \u001b[1;32mIn [7], line 19\u001b[1;36m\u001b[0m\n\u001b[1;33m    print(f”Accuracy: {accuracy}”) # Accuracy: 0.91\u001b[0m\n\u001b[1;37m           ^\u001b[0m\n\u001b[1;31mSyntaxError\u001b[0m\u001b[1;31m:\u001b[0m invalid character '”' (U+201D)\n"
     ]
    }
   ],
   "source": [
    "# Read original dataset\n",
    "iris_df = pd.read_csv(\"data/iris.csv\")\n",
    "iris_df.sample(frac=1, random_state=seed)\n",
    "# selecting features and target data\n",
    "X = iris_df[['SepalLengthCm', 'SepalWidthCm', 'PetalLengthCm', 'PetalWidthCm']]\n",
    "y = iris_df[['Species']]\n",
    "# split data into train and test sets\n",
    "# 70% training and 30% test\n",
    "X_train, X_test, y_train, y_test = train_test_split(\n",
    "X, y, test_size=0.3, random_state=seed, stratify=y)\n",
    "# create an instance of the random forest classifier\n",
    "clf = RandomForestClassifier(n_estimators=100)\n",
    "# train the classifier on the training data\n",
    "clf.fit(X_train, y_train)\n",
    "# predict on the test set\n",
    "y_pred = clf.predict(X_test)\n",
    "# calculate accuracy\n",
    "accuracy = accuracy_score(y_test, y_pred)\n",
    "print(f\"Accuracy: {accuracy}\") # Accuracy: 0.91"
   ]
  },
  {
   "cell_type": "code",
   "execution_count": 2,
   "metadata": {},
   "outputs": [
    {
     "name": "stdout",
     "output_type": "stream",
     "text": [
      "Note: you may need to restart the kernel to use updated packages.\n"
     ]
    },
    {
     "name": "stderr",
     "output_type": "stream",
     "text": [
      "WARNING: Retrying (Retry(total=4, connect=None, read=None, redirect=None, status=None)) after connection broken by 'NewConnectionError('<pip._vendor.urllib3.connection.HTTPSConnection object at 0x0000018131A391E0>: Failed to establish a new connection: [Errno 11001] getaddrinfo failed')': /simple/streamlit/\n",
      "WARNING: Retrying (Retry(total=3, connect=None, read=None, redirect=None, status=None)) after connection broken by 'NewConnectionError('<pip._vendor.urllib3.connection.HTTPSConnection object at 0x0000018131A39510>: Failed to establish a new connection: [Errno 11001] getaddrinfo failed')': /simple/streamlit/\n",
      "WARNING: Retrying (Retry(total=2, connect=None, read=None, redirect=None, status=None)) after connection broken by 'NewConnectionError('<pip._vendor.urllib3.connection.HTTPSConnection object at 0x0000018131A39840>: Failed to establish a new connection: [Errno 11001] getaddrinfo failed')': /simple/streamlit/\n",
      "WARNING: Retrying (Retry(total=1, connect=None, read=None, redirect=None, status=None)) after connection broken by 'NewConnectionError('<pip._vendor.urllib3.connection.HTTPSConnection object at 0x0000018131A399F0>: Failed to establish a new connection: [Errno 11001] getaddrinfo failed')': /simple/streamlit/\n",
      "WARNING: Retrying (Retry(total=0, connect=None, read=None, redirect=None, status=None)) after connection broken by 'NewConnectionError('<pip._vendor.urllib3.connection.HTTPSConnection object at 0x0000018131A39BA0>: Failed to establish a new connection: [Errno 11001] getaddrinfo failed')': /simple/streamlit/\n",
      "ERROR: Could not find a version that satisfies the requirement streamlit (from versions: none)\n",
      "ERROR: No matching distribution found for streamlit\n",
      "\n",
      "[notice] A new release of pip available: 22.2.2 -> 22.3.1\n",
      "[notice] To update, run: C:\\Users\\Asus\\AppData\\Local\\Microsoft\\WindowsApps\\PythonSoftwareFoundation.Python.3.10_qbz5n2kfra8p0\\python.exe -m pip install --upgrade pip\n"
     ]
    }
   ],
   "source": [
    "pip install streamlit"
   ]
  },
  {
   "cell_type": "code",
   "execution_count": 5,
   "metadata": {},
   "outputs": [
    {
     "ename": "ModuleNotFoundError",
     "evalue": "No module named 'streamlit'",
     "output_type": "error",
     "traceback": [
      "\u001b[1;31m---------------------------------------------------------------------------\u001b[0m",
      "\u001b[1;31mModuleNotFoundError\u001b[0m                       Traceback (most recent call last)",
      "Cell \u001b[1;32mIn [5], line 1\u001b[0m\n\u001b[1;32m----> 1\u001b[0m \u001b[39mimport\u001b[39;00m \u001b[39mstreamlit\u001b[39;00m \u001b[39mas\u001b[39;00m \u001b[39mst\u001b[39;00m\n",
      "\u001b[1;31mModuleNotFoundError\u001b[0m: No module named 'streamlit'"
     ]
    }
   ],
   "source": [
    "import streamlit as st"
   ]
  },
  {
   "cell_type": "code",
   "execution_count": 6,
   "metadata": {},
   "outputs": [
    {
     "ename": "SyntaxError",
     "evalue": "invalid syntax (3737097518.py, line 1)",
     "output_type": "error",
     "traceback": [
      "\u001b[1;36m  Cell \u001b[1;32mIn [6], line 1\u001b[1;36m\u001b[0m\n\u001b[1;33m    streamlit run app.py\u001b[0m\n\u001b[1;37m              ^\u001b[0m\n\u001b[1;31mSyntaxError\u001b[0m\u001b[1;31m:\u001b[0m invalid syntax\n"
     ]
    }
   ],
   "source": [
    "streamlit run app.py"
   ]
  }
 ],
 "metadata": {
  "kernelspec": {
   "display_name": "Python 3.10.8 64-bit (microsoft store)",
   "language": "python",
   "name": "python3"
  },
  "language_info": {
   "codemirror_mode": {
    "name": "ipython",
    "version": 3
   },
   "file_extension": ".py",
   "mimetype": "text/x-python",
   "name": "python",
   "nbconvert_exporter": "python",
   "pygments_lexer": "ipython3",
   "version": "3.10.8"
  },
  "orig_nbformat": 4,
  "vscode": {
   "interpreter": {
    "hash": "66f804da07f0f556d77bc3269dc5bb19edf020422864031af2885e5ff55f9079"
   }
  }
 },
 "nbformat": 4,
 "nbformat_minor": 2
}
